Workbook

Sheet Сводка
A1: База позиций США по внешнеполитическим темам
A2: Шкала оценок: от −3 (резко негативно) до +3 (резко позитивно); пустая клетка — тема не затронута. Критерии — над таблицей на листе «Таблица», цитаты — на листе «Цитаты».
A4: Сайт | B4: Документов в таблице
A5: Белый дом | B5: =COUNTIF(Таблица!$A$24:$A$836,"*whitehouse.gov*")
A6: Госдеп | B6: =COUNTIF(Таблица!$A$24:$A$836,"*state.gov*")
A7: Минобороны | B7: =COUNTIF(Таблица!$A$24:$A$836,"*war.gov*")+COUNTIF(Таблица!$A$24:$A$836,"*defense.gov*")
A8: Всего | B8: =SUM(B5:B7)
A10: Тема | B10: Документов с оценкой | C10: Средняя оценка
A11: =Таблица!I23 | B11: =COUNT(Таблица!$I$24:$I$836) | C11: =IF(B11=0,"",AVERAGE(Таблица!$I$24:$I$836))
A12: =Таблица!J23 | B12: =COUNT(Таблица!$J$24:$J$836) | C12: =IF(B12=0,"",AVERAGE(Таблица!$J$24:$J$836))
A13: =Таблица!K23 | B13: =COUNT(Таблица!$K$24:$K$836) | C13: =IF(B13=0,"",AVERAGE(Таблица!$K$24:$K$836))
A14: =Таблица!L23 | B14: =COUNT(Таблица!$L$24:$L$836) | C14: =IF(B14=0,"",AVERAGE(Таблица!$L$24:$L$836))
A15: =Таблица!M23 | B15: =COUNT(Таблица!$M$24:$M$836) | C15: =IF(B15=0,"",AVERAGE(Таблица!$M$24:$M$836))
A16: =Таблица!N23 | B16: =COUNT(Таблица!$N$24:$N$836) | C16: =IF(B16=0,"",AVERAGE(Таблица!$N$24:$N$836))
A17: =Таблица!O23 | B17: =COUNT(Таблица!$O$24:$O$836) | C17: =IF(B17=0,"",AVERAGE(Таблица!$O$24:$O$836))
A18: =Таблица!P23 | B18: =COUNT(Таблица!$P$24:$P$836) | C18: =IF(B18=0,"",AVERAGE(Таблица!$P$24:$P$836))
A19: =Таблица!Q23 | B19: =COUNT(Таблица!$Q$24:$Q$836) | C19: =IF(B19=0,"",AVERAGE(Таблица!$Q$24:$Q$836))
A20: =Таблица!R23 | B20: =COUNT(Таблица!$R$24:$R$836) | C20: =IF(B20=0,"",AVERAGE(Таблица!$R$24:$R$836))
A21: =Таблица!S23 | B21: =COUNT(Таблица!$S$24:$S$836) | C21: =IF(B21=0,"",AVERAGE(Таблица!$S$24:$S$836))
A22: =Таблица!T23 | B22: =COUNT(Таблица!$T$24:$T$836) | C22: =IF(B22=0,"",AVERAGE(Таблица!$T$24:$T$836))
A23: =Таблица!U23 | B23: =COUNT(Таблица!$U$24:$U$836) | C23: =IF(B23=0,"",AVERAGE(Таблица!$U$24:$U$836))
A24: =Таблица!V23 | B24: =COUNT(Таблица!$V$24:$V$836) | C24: =IF(B24=0,"",AVERAGE(Таблица!$V$24:$V$836))
A25: =Таблица!W23 | B25: =COUNT(Таблица!$W$24:$W$836) | C25: =IF(B25=0,"",AVERAGE(Таблица!$W$24:$W$836))

Sheet Таблица
A1: Как читать таблицу
A2: Шкала оценок | B2: от −3 до +3: −3 резко негативно, −2 негативно, −1 скорее негативно, 0 нейтрально/упомянуто без оценки, +1 скорее позитивно, +2 позитивно, +3 резко позитивно. Пустая клетка — тема в документе не затронута.
A3: Основание | B3: к каждой оценке есть дословная цитата из документа — лист «Цитаты» (строки совпадают по ссылке).
A4: Директивность | B4: 1 — указ, прокламация, меморандум, директива, соглашение, стратегия; 0 — заявления, речи, релизы.
A5: Отбор | B5: в таблицу входят только документы, где оценена хотя бы одна тема.
A6: Критерии по темам
A7: Россия | B7: −: Россия как противник, агрессор, санкции против неё; +: переговоры, жесты сближения
A8: Украинский кризис | B8: +: поддержка Украины, помощь, мирное урегулирование; −: давление на Украину
A9: Китай | B9: −2: угроза/противник; −1: конкурент; +1: партнёр по сделке, переговоры
A10: Изменение климата | B10: всегда 0, позиция описывается словами в примечании (напр. «выход из Парижского соглашения»)
A11: Миграция | B11: −3: «вторжение», чрезвычайное положение; −2: нелегальная миграция как угроза; −1: мягкое упоминание; +1: полезная легальная миграция
A12: Глобализация | B12: −: критика «глобализма», международных обязательств; +: поддержка
A13: НАТО | B13: +2: поддержка, похвала; +1: требование делить расходы; −1: «они нам не нужны»
A14: ЕС | B14: +: партнёрство; −: критика
A15: ООН | B15: −2: выход из организаций, резкая критика; −1: критика; +1: работа в органах ООН
A16: Международная торговля | B16: −1: пошлины, «нечестная торговля», дефицит; +1: торговые сделки, открытие рынков
A17: Демократии в мире | B17: +: продвижение демократии и свобод за рубежом; −: отказ от этого
A18: Военные интервенции | B18: +2: одобрение операций и ударов США; −: отказ, сворачивание
... A21: Многополярный мир | B21: +: признание баланса сил/многополярности; −: отрицание
A23: ссылка | B23: страна | C23: дата | D23: кто у власти? | E23: категория документов | F23: язык | G23: институция | H23: директивность | I23: Отношение к России | J23: Отношение к украинскому кризису | K23: Отношение к Китаю | L23: Позиция об изменении климата | M23: Позиция о миграции | N23: Отношение к глобализации | O23: Отношение к НАТО | P23: Отношение к ЕС | Q23: Отношение к ООН и дочерним организациям | R23: Отношение к международной торговле | S23: Позиция о демократиях в мире | T23: Отношение к военным интервенциям | U23: Отношение к продвижению либеральной повестки (аборты, экстремисты-ЛГБТ, легализация наркотиков) | V23: Отношение к Израилю | W23: Отношение к многополярному мировому порядку | X23: примечания (п.13 и прочее)
A24: https://www.war.gov/News/Speeches/Speech/Article/4616486/secretary-of-war-pete-hegseths-state-of-the-force-address-as-delivered | B24: Соединённые Штаты Америки | C24: 1 октября 2026 | D24: Республиканская партия (администрация Д. Трампа) | E24: выступление | F24: английский | G24: Минобороны (П. Хегсет) | H24: 0 | T24: 2 | U24: -2 | X24: либеральная повестка: -2 (отмена DEI, гендерных квот)
A25: https://www.war.gov/News/Releases/Release/Article/4614195/statement-by-chief-pentagon-spokesman-sean-parnell-on-the-conclusion-of-the-us | B25: Соединённые Штаты Америки | C25: 30 сентября 2026 | D25: Республиканская партия (администрация Д. Трампа) | E25: заявление | F25: английский | G25: Минобороны (Ш. Парнелл) | H25: 0 | T25: -1
A26: https://www.war.gov/News/Speeches/Speech/Article/4584638/remarks-by-under-secretary-of-war-for-policy-elbridge-colby-to-natos-north-atla | B26: Соединённые Штаты Америки | C26: 28 августа 2026 | D26: Республиканская партия (администрация Д. Трампа) | E26: выступление | F26: английский | G26: Минобороны (Э. Колби) | H26: 0 | J26: 1 | O26: 1 | P26: 1
A27: https://www.war.gov/News/Releases/Release/Article/4581110/department-of-war-announces-a-750-million-investment-as-part-of-a-155-billion-i | B27: Соединённые Штаты Америки | C27: 24 августа 2026 | D27: Республиканская партия (администрация Д. Трампа) | E27: пресс-релиз | F27: английский | G27: Минобороны | H27: 0 | K27: -2
A28: https://www.war.gov/News/Releases/Release/Article/4575019/department-of-war-orders-research-security-audits-at-30-academic-institutions | B28: Соединённые Штаты Америки | C28: 17 августа 2026 | D28: Республиканская партия (администрация Д. Трампа) | E28: пресс-релиз | F28: английский | G28: Минобороны | H28: 0 | K28: -1
A29: https://www.war.gov/News/Speeches/Speech/Article/4572686/secretary-of-war-pete-hegseth-delivers-remarks-at-the-americas-counter-cartel-c | B29: Соединённые Штаты Америки | C29: 13 августа 2026 | D29: Республиканская партия (администрация Д. Трампа) | E29: выступление | F29: английский | G29: Минобороны (П. Хегсет) | H29: 0 | M29: -3 | N29: -2 | T29: 2 | U29: -2 | X29: либеральная повестка: -2 (критика гендерной повестки)
A30: https://www.war.gov/News/Releases/Release/Article/4553101/the-department-of-war-releases-updated-list-of-foreign-institutions-engaging-in | B30: Соединённые Штаты Америки | C30: 23 июля 2026 | D30: Республиканская партия (администрация Д. Трампа) | E30: пресс-релиз | F30: английский | G30: Минобороны | H30: 0 | I30: -2 | K30: -2
A31: https://www.war.gov/News/Speeches/Speech/Article/4539593/remarks-by-secretary-of-war-pete-hegseth-at-the-2026-nato-defense-ministerial-i | B31: Соединённые Штаты Америки | C31: 14 июля 2026 | D31: Республиканская партия (администрация Д. Трампа) | E31: выступление | F31: английский | G31: Минобороны (П. Хегсет) | H31: 0 | J31: 1 | O31: 1 | P31: -1 | U31: -2 | X31: либеральная повестка: -2 (критика гендерного равенства в НАТО)
A32: https://www.war.gov/News/Speeches/Speech/Article/4522177/remarks-by-under-secretary-of-war-for-policy-elbridge-colby-at-the-ukraine-defe | B32: Соединённые Штаты Америки | C32: 19 июня 2026 | D32: Республиканская партия (администрация Д. Трампа) | E32: выступление | F32: английский | G32: Минобороны (Э. Колби) | H32: 0 | I32: -2 | J32: 2 | O32: 1
A33: https://www.war.gov/News/Releases/Release/Article/4521010/readout-of-secretary-of-war-pete-hegseths-meeting-with-uk-defence-secretary-dan | B33: Соединённые Штаты Америки | C33: 18 июня 2026 | D33: Республиканская партия (администрация Д. Трампа) | E33: пресс-релиз | F33: английский | G33: Минобороны (П. Хегсет) | H33: 0 | J33: 1 | O33: 1
A34: https://www.war.gov/News/Speeches/Speech/Article/4512500/remarks-by-under-secretary-of-war-for-policy-elbridge-colby-at-the-internationa | B34: Соединённые Штаты Америки | C34: 9 июня 2026 | D34: Республиканская партия (администрация Д. Трампа) | E34: выступление | F34: английский | G34: Минобороны (Э. Колби) | H34: 0 | O34: 2
A35: https://www.war.gov/News/Releases/Release/Article/4511232/dow-releases-list-of-chinese-military-companies-in-accordance-with-section-1260 | B35: Соединённые Штаты Америки | C35: 8 июня 2026 | D35: Республиканская партия (администрация Д. Трампа) | E35: пресс-релиз | F35: английский | G35: Минобороны | H35: 0 | K35: -2
A36: https://www.war.gov/News/Releases/Release/Article/4496531/statement-attributable-to-assistant-to-the-secretary-of-war-for-public-affairs | B36: Соединённые Штаты Америки | C36: 19 мая 2026 | D36: Республиканская партия (администрация Д. Трампа) | E36: заявление | F36: английский | G36: Минобороны | H36: 0 | O36: 1
A37: https://www.war.gov/News/Releases/Release/Article/4076184/secretary-of-defense-pete-hegseth-to-travel-to-guantanamo-bay | B37: Соединённые Штаты Америки | C37: 12 мая 2026 | D37: Республиканская партия (администрация Д. Трампа) | E37: пресс-релиз | F37: английский | G37: Минобороны (П. Хегсет) | H37: 0 | M37: -1
A38: https://www.war.gov/News/Speeches/Speech/Article/4442027/remarks-by-under-secretary-of-war-for-policy-elbridge-colby-at-the-ananta-centr | B38: Соединённые Штаты Америки | C38: 24 марта 2026 | D38: Республиканская партия (администрация Д. Трампа) | E38: выступление | F38: английский | G38: Минобороны (Э. Колби) | H38: 0 | R38: 1 | W38: 1
A39: https://www.war.gov/News/Speeches/Speech/Article/4404801/remarks-by-under-secretary-of-war-for-policy-elbridge-colby-at-the-nato-defense | B39: Соединённые Штаты Америки | C39: 12 февраля 2026 | D39: Республиканская партия (администрация Д. Трампа) | E39: выступление | F39: английский | G39: Минобороны (Э. Колби) | H39: 0 | J39: 1 | O39: 1
A40: https://www.war.gov/News/Releases/Release/Article/4333219/joint-media-statement-on-united-states-malaysia-bilateral-meeting | B40: Соединённые Штаты Америки | C40: 26 января 2026 | D40: Республиканская партия (администрация Д. Трампа) | E40: заявление | F40: английский | G40: Минобороны (П. Хегсет) | H40: 0 | K40: -1
A41: https://www.war.gov/News/Releases/Release/Article/4361903/readout-of-december-2025-us-china-defense-policy-coordination-talks | B41: Соединённые Штаты Америки | C41: 17 декабря 2025 | D41: Республиканская партия (администрация Д. Трампа) | E41: пресс-релиз | F41: английский | G41: Минобороны | H41: 0 | K41: 1
A42: https://www.war.gov/News/Speeches/Speech/Article/4354431/remarks-by-secretary-of-war-pete-hegseth-at-the-reagan-national-defense-forum-a | B42: Соединённые Штаты Америки | C42: 9 декабря 2025 | D42: Республиканская партия (администрация Д. Трампа) | E42: выступление | F42: английский | G42: Минобороны (П. Хегсет) | H42: 0 | I42: -1 | J42: 1 | K42: 1 | M42: -2 | O42: 1 | S42: -1 | T42: 2 | U42: -2 | V42: 2 | X42: либеральная повестка: -2 (борьба с «woke»)
A43: https://www.war.gov/News/Releases/Release/Article/4319016/department-of-war-awards-434-million-to-further-on-shore-antimony-trisulfide-pr | B43: Соединённые Штаты Америки | C43: 30 сентября 2025 | D43: Республиканская партия (администрация Д. Трампа) | E43: пресс-релиз | F43: английский | G43: Минобороны | H43: 0 | I43: -1 | K43: -1
...

Sheet Цитаты
A1: ссылка | B1: Отношение к России | C1: Отношение к украинскому кризису | D1: Отношение к Китаю | E1: Позиция об изменении климата | F1: Позиция о миграции | G1: Отношение к глобализации | H1: Отношение к НАТО | I1: Отношение к ЕС | J1: Отношение к ООН и дочерним организациям | K1: Отношение к международной торговле | L1: Позиция о демократиях в мире | M1: Отношение к военным интервенциям | N1: Отношение к продвижению либеральной повестки (аборты, экстремисты-ЛГБТ, легализация наркотиков) | O1: Отношение к Израилю | P1: Отношение к многополярному мировому порядку
A2: https://www.war.gov/News/Speeches/Speech/Article/4616486/secretary-of-war-pete-hegseths-state-of-the-force-address-as-delivered | M2: these Americans, right here, and their peers, these — have destroyed Iran's Navy | N2: No more diversity quotas, no more gender pronouns, no more identity months.
A3: https://www.war.gov/News/Releases/Release/Article/4614195/statement-by-chief-pentagon-spokesman-sean-parnell-on-the-conclusion-of-the-us | M3: The primary responsibility for addressing Iraq's remaining security challenges…now rests with the Government of Iraq
A4: https://www.war.gov/News/Speeches/Speech/Article/4584638/remarks-by-under-secretary-of-war-for-policy-elbridge-colby-to-natos-north-atla | C4: our allies can and will lead in supporting Ukraine's self-defense | H4: with our allies taking primary responsibility for Europe's conventional defense | I4: the goal is for Europeans to be partners, not dependencies
A5: https://www.war.gov/News/Releases/Release/Article/4581110/department-of-war-announces-a-750-million-investment-as-part-of-a-155-billion-i | D5: This initiative aggressively addresses an over-dependence on China for rare-earth elements.
A6: https://www.war.gov/News/Releases/Release/Article/4575019/department-of-war-orders-research-security-audits-at-30-academic-institutions | D6: organizations associated with rebranded Confucius Institutes
A7: https://www.war.gov/News/Speeches/Speech/Article/4572686/secretary-of-war-pete-hegseth-delivers-remarks-at-the-americas-counter-cartel-c | F7: openly accepting mass illegal immigration and destroying many of our great American cities — an invasion, no doubt. | G7: Under decades of globalist neglect more than 1 million Americans died from fentanyl | M7: It's now nearly one year since the launch of Operation Southern Spear…And it has been a resounding success thus far. | N7: promoting priorities like gender issues, women, peace and security, or climate change or diversity — dudes in dresses.
A8: https://www.war.gov/News/Releases/Release/Article/4553101/the-department-of-war-releases-updated-list-of-foreign-institutions-engaging-in | B8: The FY25 list formally identifies 130 academic and research institutions located in China, Russia and Iran. | D8: The FY25 list formally identifies 130 academic and research institutions located in China, Russia and Iran.
A9: https://www.war.gov/News/Speeches/Speech/Article/4539593/remarks-by-secretary-of-war-pete-hegseth-at-the-2026-nato-defense-ministerial-i | C9: allies have taken the lead in funding support for Ukraine's defense | H9: for too long, NATO has been a paper tiger and a one-way street | I9: Europe's borders flew wide open, welfare states expanded, defense budgets cratered | N9: the focus had been on gender equity and climate change and defense austerity
A10: https://www.war.gov/News/Speeches/Speech/Article/4522177/remarks-by-under-secretary-of-war-for-policy-elbridge-colby-at-the-ukraine-defe | B10: Russia's understanding that perpetuating this war is not only condemnable but also will not pay off for Moscow | C10: Ukraine's defense does hold but continued and sustained support from allies is essential to maintain it. | H10: It is important that NATO allies continue — and indeed, increase — their support for Ukraine's defense
A11: https://www.war.gov/News/Releases/Release/Article/4521010/readout-of-secretary-of-war-pete-hegseths-meeting-with-uk-defence-secretary-dan | C11: including support for Ukraine's defense | H11: the critical need for all allies…to show rapid progress toward their Hague Summit pledge of 5% of GDP on defense spending
A12: https://www.war.gov/News/Speeches/Speech/Article/4512500/remarks-by-under-secretary-of-war-for-policy-elbridge-colby-at-the-internationa | H12: are striving together to build a renewed NATO
A13: https://www.war.gov/News/Releases/Release/Article/4511232/dow-releases-list-of-chinese-military-companies-in-accordance-with-section-1260 | D13: names of "Chinese military companies" operating directly or indirectly in the United States
A14: https://www.war.gov/News/Releases/Release/Article/4496531/statement-attributable-to-assistant-to-the-secretary-of-war-for-public-affairs | H14: incentivizing and enabling our NATO allies to take primary responsibility for Europe's conventional defense
A15: https://www.war.gov/News/Releases/Release/Article/4076184/secretary-of-defense-pete-hegseth-to-travel-to-guantanamo-bay | F15: It also facilitates temporary detention of illegal aliens who are pending return to their country of origin
A16: https://www.war.gov/News/Speeches/Speech/Article/4442027/remarks-by-under-secretary-of-war-for-policy-elbridge-colby-at-the-ananta-centr | K16: Both benefit from open trade and national autonomy. | P16: Both of our countries benefit from an Indo-Pacific in which no power can dominate the region.
A17: https://www.war.gov/News/Speeches/Speech/Article/4404801/remarks-by-under-secretary-of-war-for-policy-elbridge-colby-at-the-nato-defense | C17: negotiate an end to the tragic war in Ukraine | H17: This "NATO 3.0" requires much greater efforts by our allies to step up and assume primary responsibility for the conventional defense of Europe.
A18: https://www.war.gov/News/Releases/Release/Article/4333219/joint-media-statement-on-united-states-malaysia-bilateral-meeting | D18: grey-zone tactics, such as hydrographic research conducted under the protection of foreign coast guard vessels, threaten sovereignty
A19: https://www.war.gov/News/Releases/Release/Article/4361903/readout-of-december-2025-us-china-defense-policy-coordination-talks | D19: achieve a stable peace and respectful relations between the United States and China
A20: https://www.war.gov/News/Speeches/Speech/Article/4354431/remarks-by-secretary-of-war-pete-hegseth-at-the-reagan-national-defense-forum-a | B20: Vladimir Putin saw the open door and he took it | C20: we are working tirelessly to end the tragic war in Ukraine | D20: relations between the United States and China are better and stronger than they've been in many years | F20: tens of millions of illegals | H20: NATO committed to spend 5% of GDP | L20: the War Department will not be distracted by democracy building interventionism | M20: With Operation Midnight Hammer, the world saw, after decades of hemming and hawing, the decisive effect of American military strength | N20: Wokeness, weakness, war. | O20: Model allies that step up like Israel
A21: https://www.war.gov/News/Releases/Release/Article/4319016/department-of-war-awards-434-million-to-further-on-shore-antimony-trisulfide-pr | B21: China and Russia control the market for antimony and all its derivatives, putting the United States at risk | D21: China and Russia control the market for antimony and all its derivatives, putting the United States at risk
A22: https://www.war.gov/News/Releases/Release/Article/4313160/readout-of-secretary-of-war-pete-hegseths-meeting-with-canadian-minister-of-nat | H22: vital importance of Canada stepping up to meet its historic Hague Summit commitment
A23: https://www.war.gov/News/Releases/Release/Article/4313389/readout-of-secretary-of-war-pete-hegseths-call-with-estonian-minister-of-defenc | H23: the Department of War stands with all NATO allies and that any incursion into NATO airspace is unacceptable
A24: https://www.war.gov/News/Releases/Release/Article/4299101/readout-of-secretary-of-war-pete-hegseths-call-with-peoples-republic-of-china-m | D24: the United States does not seek conflict with China nor is it pursuing regime change or strangulation of the PRC
A25: https://www.war.gov/News/Releases/Release/Article/4300023/trump-administration-announces-security-assistance-package-for-lebanon | O25: in support of the November 2024 Cessation of Hostilities between Lebanon and Israel
A26: https://www.defense.gov/News/Releases/Release/Article/4270722/office-of-strategic-capital-announces-first-loan-through-dod-agreement-with-mp | D26: The Chinese Communist Party has implemented aggressive actions to endanger the global critical minerals supply chain
A27: https://www.defense.gov/News/Releases/Release/Article/4244370/readout-of-secretary-of-defense-pete-hegseths-meeting-with-the-federal-minister | C27: set conditions for an end to the war in Ukraine on terms that support an enduring peace | H27: securing historic commitments by NATO allies at last month's NATO Summit at The Hague to meet President Trump's call to spend 5% of GDP on defense
A28: https://www.defense.gov/News/Releases/Release/Article/4238823/readout-of-secretary-of-defense-pete-hegseths-meeting-with-israel-prime-ministe | M28: brave U.S. servicemembers who executed this perfect operation | O28: the United States remains committed to supporting Israel
A29: https://www.defense.gov/News/Releases/Release/Article/4201764/readout-of-secretary-hegseths-meeting-with-southeast-asian-defense-ministers | D29: Secretary Hegseth reiterated concerns about coercive activity by China against South China Sea claimant countries
A30: https://www.defense.gov/News/Releases/Release/Article/4180537/statement-by-chief-pentagon-spokesman-and-senior-advisor-sean-parnell-on-review | N30: should be mission-focused and not promote divisive concepts and gender ideology
A31: https://www.defense.gov/News/Releases/Release/Article/4151039/statement-by-chief-pentagon-spokesman-sean-parnell | D31: We are taking back the Panama Canal from malign Chinese influence
A32: https://www.defense.gov/News/Releases/Release/Article/4149739/joint-statement-between-president-mulino-panama-canal-authority-administrator-a | D32: exit the Belt and Road Initiative, and to reduce China's problematic presence | F32: Panama's efforts to reduce illegal immigration and for closing the border in the Darién
A33: https://www.defense.gov/News/Releases/Release/Article/4148095/readout-of-secretary-of-defense-pete-hegseths-call-with-the-united-kingdoms-sec | C33: thanked the UK for its leadership in chairing the Ukraine Defense Contact Group | M33: the recent strikes against the Houthi terrorists in Yemen
A34: https://www.defense.gov/News/Releases/Release/Article/4086539/dod-statement-on-deployment-of-stryker-brigade-combat-team-to-help-secure-our-s | F34: to seal the border and protect the territorial integrity of the United States
A35: https://www.defense.gov/News/Releases/Release/Article/4079501/pentagon-releases-digital-content-refresh-memorandum | N35: remove and archive DoD news articles, photos, and videos promoting Diversity, Equity, and Inclusion (DEI)
A36: https://www.defense.gov/News/Releases/Release/Article/4071336/department-of-defense-chief-of-staff-joseph-kasper-statement-on-us-northcom-com | F36: cooperation on security along the Mexico and U.S. border
A37: https://www.defense.gov/News/Releases/Release/Article/4071371/statement-by-performing-the-duties-of-deputy-secretary-of-defense-robert-g-sale | E37: so-called "climate change" and other woke programs | F37: Securing our borders | N37: ending radical and wasteful government DEI programs and preferencing
A38: https://www.defense.gov/News/Releases/Release/Article/4068754/readout-of-secretary-of-defense-pete-hegseths-meetings-with-the-president-of-th | H38: Poland is a model ally on defense spending and modernization efforts — setting the example for NATO burden-sharing commitments
A39: https://www.defense.gov/News/Releases/Release/Article/4065012/readout-of-secretary-of-defense-pete-hegseths-meeting-with-the-united-kingdoms | C39: the need to set the stage for negotiations to stop the fighting and reach an enduring peace | H39: greater burden-sharing by European Allies
A40: https://www.defense.gov/News/Releases/Release/Article/4065017/readout-of-secretary-of-defense-pete-hegseths-meeting-with-german-minister-of-d | C40: supporting diplomatic efforts to achieve a durable peace in Ukraine | H40: a strong focus on Allied defense spending
...
